Lmod has detected the following error: The following module(s) are unknown:
"gcc/8.4.0/1"

Please check the spelling or version number. Also try "module spider ..."
It is also possible your cache file is out-of-date; it may help to try:
  $ module --ignore_cache load "gcc/8.4.0/1"

Also make sure that all modulefiles written in TCL start with the string
#%Module



[2025-05-04 23:02:28,825] torch.distributed.run: [WARNING] 
[2025-05-04 23:02:28,825] torch.distributed.run: [WARNING] *****************************************
[2025-05-04 23:02:28,825] torch.distributed.run: [WARNING] Setting OMP_NUM_THREADS environment variable for each process to be 1 in default, to avoid your system being overloaded, please further tune the variable for optimal performance in your application as needed. 
[2025-05-04 23:02:28,825] torch.distributed.run: [WARNING] *****************************************
Traceback (most recent call last):
  File "/insomnia001/depts/edu/COMSE6998/ck3255/beir/examples/retrieval/training/train_sbert_ddp_2.py", line 7, in <module>
    from sentence_transformers import SentenceTransformer, losses, InputExample
ModuleNotFoundError: No module named 'sentence_transformers'
Traceback (most recent call last):
  File "/insomnia001/depts/edu/COMSE6998/ck3255/beir/examples/retrieval/training/train_sbert_ddp_2.py", line 7, in <module>
    from sentence_transformers import SentenceTransformer, losses, InputExample
ModuleNotFoundError: No module named 'sentence_transformers'
[2025-05-04 23:02:33,849] torch.distributed.elastic.multiprocessing.api: [ERROR] failed (exitcode: 1) local_rank: 0 (pid: 1937437) of binary: /usr/bin/python3
Traceback (most recent call last):
  File "/usr/local/bin/torchrun", line 8, in <module>
    sys.exit(main())
  File "/insomnia001/depts/edu/COMSE6998/ck3255/anaconda3/envs/myenv39/lib/python3.9/site-packages/torch/distributed/elastic/multiprocessing/errors/__init__.py", line 346, in wrapper
    return f(*args, **kwargs)
  File "/insomnia001/depts/edu/COMSE6998/ck3255/anaconda3/envs/myenv39/lib/python3.9/site-packages/torch/distributed/run.py", line 806, in main
    run(args)
  File "/insomnia001/depts/edu/COMSE6998/ck3255/anaconda3/envs/myenv39/lib/python3.9/site-packages/torch/distributed/run.py", line 797, in run
    elastic_launch(
  File "/insomnia001/depts/edu/COMSE6998/ck3255/anaconda3/envs/myenv39/lib/python3.9/site-packages/torch/distributed/launcher/api.py", line 134, in __call__
    return launch_agent(self._config, self._entrypoint, list(args))
  File "/insomnia001/depts/edu/COMSE6998/ck3255/anaconda3/envs/myenv39/lib/python3.9/site-packages/torch/distributed/launcher/api.py", line 264, in launch_agent
    raise ChildFailedError(
torch.distributed.elastic.multiprocessing.errors.ChildFailedError: 
============================================================
/insomnia001/depts/edu/COMSE6998/ck3255/beir/examples/retrieval/training/train_sbert_ddp_2.py FAILED
------------------------------------------------------------
Failures:
[1]:
  time      : 2025-05-04_23:02:33
  host      : 2402-node056.ins
  rank      : 1 (local_rank: 1)
  exitcode  : 1 (pid: 1937438)
  error_file: <N/A>
  traceback : To enable traceback see: https://pytorch.org/docs/stable/elastic/errors.html
------------------------------------------------------------
Root Cause (first observed failure):
[0]:
  time      : 2025-05-04_23:02:33
  host      : 2402-node056.ins
  rank      : 0 (local_rank: 0)
  exitcode  : 1 (pid: 1937437)
  error_file: <N/A>
  traceback : To enable traceback see: https://pytorch.org/docs/stable/elastic/errors.html
============================================================
